Workbook

Sheet INSTRUCOES
A1: TCC — Instrumento de controle do experimento
A2: Avaliação de processos de Inteligência Artificial Generativa na geração e automação de cenários de teste em Gherkin (BDD) para apoio à qualidade de software
A3: Keurliano Araújo Lima — IFSC, Câmpus Florianópolis
A5: 1. LEGENDA DE CORES
A6: Fundo amarelo | C6: Campo de preenchimento manual. A formatação condicional destaca em amarelo as células ainda vazias das linhas já iniciadas.
A7: Fundo verde | C7: Célula calculada por fórmula. Não editar.
A8: Sem preenchimento | C8: Campo opcional ou de texto livre.
A10: 2. PARÂMETROS FIXOS DO EXPERIMENTO
C11: As três condições devem usar os mesmos parâmetros. Preencha aqui uma única vez: as abas C0, C1 e C2 puxam estes valores automaticamente.
A12: Modelo de IA | B12: GPT-5.6 Luna (Free)
A13: Versão do modelo | B13: Instant
A14: Temperatura | B14: Não disponibilizada pela interface
A15: Top-p | B15: Não disponibilizado pela interface
A16: Condições | B16: C0, C1 e C2
A17: Histórias | B17: H1, H2 e H3
A18: Execuções por condição/história | B18: 3
A20: 3. CONTROLE DE CONGELAMENTO DO GABARITO
C21: O gabarito deve ser construído e congelado ANTES de qualquer geração pela IA. Após o congelamento, as regras não devem ser alteradas para acomodar o que a IA produziu. Se um erro real for identificado antes da geração, registre nova versão e justifique.
A22: Versão atual do gabarito
A23: Responsável pela revisão
A24: Data da revisão
A25: Data de congelamento
A26: Status
A27: Justificativa de nova versão (se houver)
A29: 4. ORDEM DE PREENCHIMENTO
A30: Passo 1 | C30: HISTORIAS — registrar as candidatas, aplicar os critérios de seleção e definir o status de cada uma.
A31: Passo 2 | C31: GABARITO — enumerar regras de negócio, critérios de aceitação e cenários esperados, com evidência para cada linha.
A32: Passo 3 | C32: TABELA_DECISAO — modelar as combinações de condições e ações de cada história.
A33: Passo 4 | C33: Congelar o gabarito e registrar o congelamento no bloco 3 desta aba.
A34: Passo 5 | C34: C0, C1 e C2 — executar as gerações e registrar prompt, entradas e saída bruta de cada execução.
A35: Passo 6 | C35: RASTREABILIDADE — lançar uma linha por cenário gerado, associando-o (ou não) a uma regra do gabarito.
A36: Passo 7 | C36: INTERVENCOES — registrar cada correção humana realizada.
A37: Passo 8 | C37: AUTOMACAO — registrar implementação e execução das definições de passo.
A38: Passo 9 | C38: RESUMO — conferir as métricas calculadas e preencher os campos de apuração manual.
A40: 5. ABA AUXILIAR
A41: APURACAO | C41: Aba de apoio ao cálculo. Espelha linha a linha o GABARITO e marca, por condição, se cada regra e cada cenário de exceção foi coberto. É lida pela aba RESUMO. Não editar.
A43: 6. EXEMPLOS DE PREENCHIMENTO
C44: As linhas abaixo mostram apenas o formato esperado de cada campo. NÃO são dados do experimento e não devem ser copiadas para as demais abas.
A46: EXEMPLO – NÃO FAZ PARTE DOS RESULTADOS
A47: GABARITO | C47: História ID = H1 | Regra ID = H1-RN-01 | Critério ID = H1-CA-01 | Cenário esperado ID = H1-CE-01 | Tipo de cenário = Principal | Exceção? = Não | Fonte/evidência = observação da aplicação em 2026-09-14, tela de login
...

Sheet HISTORIAS
A1: HISTORIAS — candidatas e seleção
A2: Registro das histórias de usuário do SauceDemo consideradas para o experimento. As três linhas abaixo são candidatas preliminares, não seleções confirmadas.
A3: ID da história | B3: Nome da funcionalidade | C3: História de usuário | D3: Objetivo | E3: Critérios de seleção atendidos | F3: Pontuação da matriz de seleção | G3: Justificativa da seleção | H3: Status da seleção | I3: Observações
A4: H01 | B4: Login / Autenticação | C4: Como usuário do sistema, quero informar meu nome de usuário e minha senha, para acessar a área de produtos quando minhas credenciais forem válidas. | H4: Candidata | I4: Registro preliminar. A seleção só se confirma após a aplicação dos critérios definidos na metodologia.
A5: H02 | B5: Carrinho de compras | C5: Como usuário autenticado, quero adicionar produtos ao carrinho e visualizar e gerenciar os itens selecionados, para revisar minha seleção antes de realizar o checkout. | H5: Candidata | I5: Registro preliminar. A seleção só se confirma após a aplicação dos critérios definidos na metodologia.
A6: H03 | B6: Checkout / Finalização da compra | C6: Como usuário autenticado, quero informar meus dados e finalizar a compra, para concluir o processo de aquisição dos produtos selecionados. | H6: Candidata | I6: Registro preliminar. A seleção só se confirma após a aplicação dos critérios definidos na metodologia.

Sheet GABARITO
A1: GABARITO — regras, critérios e cenários esperados
A2: Construído manualmente ANTES de qualquer geração pela IA. Uma linha por cenário esperado. Não preencher regra ou cenário sem evidência registrada na coluna Fonte/evidência.
A3: História ID | B3: Regra ID | C3: Regra de negócio | D3: Critério de aceitação ID | E3: Critério de aceitação | F3: Tipo de regra | G3: Cenário esperado ID | H3: Descrição do cenário esperado | I3: Tipo de cenário | J3: Exceção? | K3: Condição inicial | L3: Resultado esperado | M3: Fonte/evidência | N3: Observações | O3: Status de revisão | P3: Data de congelamento | Q3: Data da revisão | R3: Responsável pela revisão
A4: H01 | B4: RN02 | C4: O Username deve ser informado para que a autenticação seja realizada. | D4: CA01 | E4: Dado que o usuário esteja na tela de login, ao não informar Username e tentar realizar o login, o sistema deve informar que o Username é obrigatório. | F4: Obrigatoriedade | G4: SC01 | H4: Tentativa de login sem informar Username | I4: Negativo | J4: Não | K4: Usuário na tela de login, Username e Password não informados | L4: Impedir a autenticação e informar que o Username é obrigatório. | M4: Teste manual no SauceDemo: tentativa de login sem Username apresentou a mensagem de obrigatoriedade do Username. | N4: Cenário relacionado à validação de campo obrigatório. | O4: Em revisão | P4: 46294 | Q4: 46293 | R4: Keurliano Araújo
A5: H01 | B5: RN03 | C5: A Password deve ser informada para que a autenticação seja realizada. | D5: CA02 | E5: Dado que o Username tenha sido informado, ao não informar Password e tentar realizar o login, o sistema deve informar que a Password é obrigatória. | F5: Obrigatoriedade | G5: SC02 | H5: Tentativa de login sem informar Password | I5: Negativo | J5: Não | K5: Username informado e Password não informada | L5: Impedir a autenticação e informar que a Password é obrigatória. | M5: Teste manual no SauceDemo: tentativa de login sem Password apresentou a mensagem de obrigatoriedade da Password. | N5: Cenário relacionado à validação de campo obrigatório. | O5: Em revisão | P5: 46294 | Q5: 46293 | R5: Keurliano Araújo
A6: H01 | B6: RN04 | C6: O sistema deve rejeitar credenciais que não correspondam a um usuário válido. | D6: CA03 | E6: Dado que o usuário informe um Username inexistente e uma Password, o sistema deve impedir o acesso e informar que as credenciais não correspondem a um usuário disponível. | F6: Validação | G6: SC03 | H6: Tentativa de login com Username inexistente | I6: Negativo | J6: Não | K6: Username inexistente e Password informada | L6: Impedir a autenticação e informar que Username e Password não correspondem a um usuário disponível. | M6: Teste manual no SauceDemo: tentativa com Username inexistente apresentou mensagem de credenciais inválidas. | N6: Cenário de credenciais inválidas por Username inexistente. | O6: Em revisão | P6: 46294 | Q6: 46293 | R6: Keurliano Araújo
A7: H01 | B7: RN04 | C7: O sistema deve rejeitar credenciais que não correspondam a um usuário válido. | D7: CA04 | E7: Dado que o usuário informe um Username válido e uma Password incorreta, o sistema deve impedir o acesso e informar que as credenciais não correspondem a um usuário disponível. | F7: Validação | G7: SC04 | H7: Tentativa de login com Password incorreta | I7: Negativo | J7: Não | K7: Username válido e Password incorreta | L7: Impedir a autenticação e informar que Username e Password não correspondem a um usuário disponível. | M7: Teste manual no SauceDemo: tentativa com Username válido e Password incorreta apresentou mensagem de credenciais inválidas. | N7: Cenário de credenciais inválidas por Password incorreta. | O7: Em revisão | P7: 46294 | Q7: 46293 | R7: Keurliano Araújo
A8: H01 | B8: RN05 | C8: O sistema deve impedir o acesso de um usuário bloqueado. | D8: CA05 | E8: Dado que o usuário informe as credenciais de locked_out_user, o sistema deve impedir o acesso e informar que o usuário está bloqueado. | F8: Restrição | G8: SC05 | H8: Tentativa de login com usuário bloqueado | I8: Exceção | J8: Sim | K8: Username locked_out_user e Password secret_sauce | L8: Impedir a autenticação e informar que o usuário está bloqueado. | M8: Teste manual no SauceDemo: tentativa com locked_out_user e secret_sauce apresentou mensagem de usuário bloqueado. | N8: Comportamento de exceção observado no ambiente. | O8: Em revisão | P8: 46294 | Q8: 46293 | R8: Keurliano Araújo
A9: H01 | B9: RN06 | C9: O sistema deve permitir o acesso quando forem utilizadas credenciais válidas. | D9: CA06 | E9: Dado que o usuário informe credenciais válidas, o sistema deve permitir o acesso. Após o login realizado com sucesso, o sistema deve direcionar o usuário para a área de produtos. | F9: Autenticação/Fluxo | G9: SC06 | H9: Login com credenciais válidas | I9: Positivo | J9: Não | K9: Username standard_user e Password secret_sauce | L9: Permitir a autenticação e direcionar o usuário para a área de produtos. | M9: Teste manual no SauceDemo: autenticação com standard_user e secret_sauce permitiu acesso à área de produtos. | N9: Um único cenário cobre o comportamento de autenticação e o fluxo posterior. | O9: Em revisão | P9: 46294 | Q9: 46293 | R9: Keurliano Araújo
A10: H01 | B10: RN07 | C10: Após uma autenticação válida, o usuário deve ser direcionado para a área de produtos. | D10: CA07 | E10: Após o login realizado com sucesso, o usuário deve ser direcionado para a área de produtos. | F10: Autenticação/Fluxo | G10: SC06 | H10: Acesso à área de produtos após autenticação válida | I10: Positivo | J10: Não | K10: O usuário está na tela de login e possui credenciais válidas de um usuário não bloqueado. | L10: O sistema deve permitir a autenticação e direcionar o usuário para a área de produtos. | M10: Teste manual no SauceDemo | N10: N/A | O10: Em revisão | P10: 46294 | Q10: 46293 | R10: Keurliano Araújo
A12: H02 | B12: RN08 | C12: O sistema deve permitir que o usuário adicione um produto ao carrinho. | D12: CA08 | E12: Dado que o usuário esteja na área de produtos, ao selecionar a opção para adicionar um produto ao carrinho, o sistema deve adicionar o produto ao carrinho e atualizar o indicador de quantidade do carrinho. | F12: Autenticação/Fluxo | G12: SC07 | H12: Adição de um produto ao carrinho | I12: Positivo | J12: Não | K12: Usuário autenticado e na área de produtos, com pelo menos um produto disponível | L12: O produto selecionado é adicionado ao carrinho e o indicador de quantidade é atualizado | M12: Teste manual realizado no ambiente SauceDemo | N12: Cenário relacionado à adição de produto ao carrinho | O12: Em revisão | P12: 46294 | Q12: 46293 | R12: Keurliano Araújo
A13: H02 | B13: RN09 | C13: O sistema não deve permitir que o mesmo produto seja adicionado mais de uma vez ao carrinho. | D13: CA09 | E13: Dado que um produto já tenha sido adicionado ao carrinho, ao tentar adicioná-lo novamente, o sistema não deve adicionar uma segunda ocorrência do mesmo produto. | F13: Restrição | G13: SC08 | H13: Tentativa de adicionar novamente um produto que já está no carrinho | I13: Exceção | J13: Sim | K13: Usuário autenticado e com um produto já adicionado ao carrinho | L13: O sistema não adiciona uma segunda ocorrência do mesmo produto | M13: Teste manual realizado no ambiente SauceDemo | N13: Cenário relacionado à restrição de duplicidade de produtos | O13: Em revisão | P13: 46294 | Q13: 46293 | R13: Keurliano Araújo
A14: H02 | B14: RN10 | C14: O sistema deve apresentar no carrinho os produtos que foram adicionados pelo usuário, juntamente com suas informações de identificação, quantidade e preço. | D14: CA10 | E14: Dado que o usuário tenha adicionado produtos ao carrinho, ao acessar o carrinho, o sistema deve apresentar os produtos selecionados juntamente com suas informações de identificação, quantidade e preço. | F14: Autenticação/Fluxo | G14: SC09 | H14: Visualização dos produtos adicionados no carrinho | I14: Positivo | J14: Não | K14: Usuário autenticado e com um ou mais produtos adicionados ao carrinho | L14: O carrinho apresenta os produtos selecionados, juntamente com suas informações de identificação, quantidade e preço | M14: Teste manual realizado no ambiente SauceDemo | N14: Cenário relacionado à apresentação dos itens do carrinho | O14: Em revisão | P14: 46294 | Q14: 46293 | R14: Keurliano Araújo
A15: H02 | B15: RN11 | C15: O sistema deve permitir que o usuário remova produtos do carrinho. | D15: CA11 | E15: Dado que existam produtos no carrinho, ao selecionar a opção de remover um produto, o sistema deve retirar o produto do carrinho e atualizar o indicador de quantidade. | F15: Autenticação/Fluxo | G15: SC10 | H15: Remoção de um produto do carrinho | I15: Positivo | J15: Não | K15: Usuário autenticado e com pelo menos dois produtos no carrinho | L15: O produto selecionado é removido do carrinho e o indicador de quantidade é atualizado, mantendo os demais produtos | M15: Teste manual realizado no ambiente SauceDemo | N15: Cenário relacionado à remoção de um item sem esvaziar o carrinho | O15: Em revisão | P15: 46294 | Q15: 46293 | R15: Keurliano Araújo
A16: H02 | B16: RN12 | C16: O sistema deve permitir que o carrinho permaneça sem produtos após a remoção de todos os itens. | D16: CA12 | E16: Dado que existam produtos no carrinho, ao remover todos os produtos, o sistema deve manter o carrinho sem itens. | F16: Restrição | G16: SC11 | H16: Remoção de todos os produtos do carrinho | I16: Exceção | J16: Sim | K16: Usuário autenticado e com um ou mais produtos no carrinho | L16: O carrinho permanece sem produtos após a remoção de todos os itens | M16: Teste manual realizado no ambiente SauceDemo | N16: Cenário relacionado ao estado vazio do carrinho após a remoção dos itens | O16: Em revisão | P16: 46294 | Q16: 46293 | R16: Keurliano Araújo
... A29: H03 | B29: RN24 | C29: O sistema deve permitir que o usuário gere o PDF do pedido após a conclusão da compra. | D29: CA24 | E29: Dado que o usuário esteja na página Checkout: Complete!, ao selecionar a opção Gerar o PDF do pedido, o sistema deve gerar e baixar um documento contendo as informações do recibo do pedido. | F29: Autenticação/Fluxo | G29: SC21 | H29: Geração e download do PDF do pedido após a conclusão da compra | I29: Positivo | J29: Não | K29: Usuário está na página Checkout: Complete! após finalizar a compra. | L29: Ao selecionar a opção “Gerar o PDF do pedido”, o sistema gera e baixa um documento contendo as informações do recibo do pedido. | M29: Teste manual realizado no ambiente SauceDemo: a seleção de “Gerar o PDF do pedido” realizou o download do documento contendo as informações do recibo do pedido | N29: Cenário relacionado à geração do documento do pedido após a conclusão da compra | O29: Em revisão | P29: 46294 | Q29: 46293 | R29: Keurliano Araújo

Sheet TABELA_DECISAO
A2: Uma linha por combinação de condições. Foram previstas seis colunas de condição; use apenas as necessárias em cada história e deixe as demais em branco.
A3: História ID | B3: Cenário ID | C3: Condição 1 | D3: Condição 2 | E3: Condição 3 | F3: Ação esperada | G3: Regra ID relacionada | H3: Tipo de cenário | I3: Observações
A4: H01 | B4: TD01 | C4: Username não informado | D4: Password não informada | E4: Não se Aplica | F4: Impedir autenticação e informar que o Username é obrigatório | G4: RN02 | H4: Negativo | I4: Ao clicar em Login sem preencher os campos
A5: H01 | B5: TD02 | C5: Username informado | D5: Password não informada | E5: Não se Aplica | F5: Impedir autenticação e informar que a Password é obrigatória | G5: RN03 | H5: Negativo | I5: Username informado e Password vazia
A6: H01 | B6: TD03 | C6: Username inexistente | D6: Password informada | E6: Não se Aplica | F6: Impedir autenticação e informar que Username e Password não correspondem a um usuário disponível | G6: RN04 | H6: Negativo | I6: Utilizar um Username que não exista no ambiente
A7: H01 | B7: TD04 | C7: Username válido | D7: Password incorreta | E7: Não bloqueado | F7: Impedir autenticação e informar que Username e Password não correspondem a um usuário disponível | G7: RN04 | H7: Negativo | I7: Utilizar usuário válido com senha diferente de secret_sauce
A8: H01 | B8: TD05 | C8: Username = locked_out_user | D8: Password = secret_sauce | E8: Bloqueado | F8: Impedir autenticação e informar que o usuário está bloqueado | G8: RN05 | H8: Exceção | I8: Comportamento observado no ambiente
A9: H01 | B9: TD06 | C9: Username válido | D9: Password válida | E9: Não bloqueado | F9: Permitir autenticação e direcionar para a área de produtos | G9: RN06, RN07 | H9: Positivo | I9: Utilizar, por exemplo, standard_user + secret_sauce
A11: H02 | B11: TD07 | C11: Produto disponível na área de produtos | D11: Produto ainda não está no carrinho | E11: Usuário autenticado | F11: Adicionar o produto ao carrinho e atualizar o indicador de quantidade | G11: RN08 | H11: Positivo | I11: Selecionar a opção de adicionar um produto ao carrinho
A12: H02 | B12: TD08 | C12: Produto disponível na área de produtos | D12: Produto já está no carrinho | E12: Usuário autenticado | F12: Impedir a adição de uma segunda ocorrência do mesmo produto | G12: RN09 | H12: Exceção | I12: Tentar adicionar novamente um produto que já foi adicionado
A13: H02 | B13: TD09 | C13: Um ou mais produtos adicionados | D13: Usuário acessa o carrinho | E13: Usuário autenticado | F13: Apresentar os produtos selecionados com suas informações de identificação, quantidade e preço | G13: RN10 | H13: Positivo | I13: Verificar as informações apresentadas para os produtos
A14: H02 | B14: TD10 | C14: Dois ou mais produtos no carrinho | D14: Um dos produtos é selecionado para remoção | E14: Usuário autenticado | F14: Remover o produto selecionado e atualizar o indicador de quantidade, mantendo os demais produtos | G14: RN11 | H14: Positivo | I14: Verificar que os demais produtos permanecem no carrinho
A15: H02 | B15: TD11 | C15: Um ou mais produtos no carrinho | D15: Todos os produtos são removidos | E15: Usuário autenticado | F15: Manter o carrinho sem produtos | G15: RN12 | H15: Exceção | I15: Representa o estado vazio do carrinho após a remoção
... A26: H03 | B26: TD21 | C26: Usuário está na página Checkout: Complete! | D26: Opção “Gerar o PDF do pedido” selecionada | E26: Não se Aplica | F26: Gerar e baixar um documento contendo as informações do recibo do pedido | G26: RN24 | H26: Positivo | I26: Gerar e baixar um documento contendo as informações do recibo do pedido

Sheet C0
A1: C0 — abordagem não estruturada
A2: História de usuário e prompt mínimo, sem informações estruturadas adicionais e sem processo de validação. Modelo, versão, temperatura e top-p são puxados da aba INSTRUCOES para garantir que as três condições usem os mesmos parâmetros.
A3: História ID | B3: Execução ID | C3: Data | D3: Modelo | E3: Versão do modelo | F3: Temperatura | G3: Top-p | H3: Prompt utilizado | I3: Entrada fornecida | J3: Saída bruta da IA | K3: Arquivo da saída bruta (caminho ou link) | L3: Quantidade de cenários gerados | M3: Observações
A4: H1 | B4: E1 | D4: GPT-5.6 Luna | E4: =IF(INSTRUCOES!$B$13="","",INSTRUCOES!$B$13) -> Instant | F4: =IF(INSTRUCOES!$B$14="","",INSTRUCOES!$B$14) -> Não disponibilizada pela interface | G4: =IF(INSTRUCOES!$B$15="","",INSTRUCOES!$B$15) -> Não disponibilizado pela interface | H4: Você é um analista de testes de software com conhecimento em BDD e na linguagem Gherkin. A partir da história de usuário apresentada abaixo, gere cenários de teste em Gherkin que representem os comportamentos que devem ser testados no sistema. Considere as informações disponíveis na história de usuário e utilize seu conhecimento para identificar os principais cenários de teste, incluindo situações de sucesso e situações de erro ou exceção. Utilize uma estrutura válida de Gherkin, com as palavras-chave Feature, Scenario, Given, When, Then, And e But quando necessário. Não explique sua resposta. Apresente somente os cenários Gherkin. História de usuário: Como usuário do sistema, quero informar meu nome de usuário e minha senha, para acessar a área de produtos quando minhas credenciais forem válidas. | J4: Feature: Login de usuário Scenario: Acessar a área de produtos com credenciais válidas Given que o usuário está na tela de login And possui um nome de usuário e uma senha válidos When informar o nome de usuário válido And informar a senha válida And solicitar o acesso Then o sistema deve autenticar o usuário And permitir o acesso à área de produtos Scenario: Tentar acessar com nome de usuário inválido Given que o usuário está na tela de login And possui uma senha válida When informar um nome de usuário inválido And informar a senha válida And solicitar o acesso Then o sistema deve negar o acesso And exibir uma mensagem informando que as credenciais são inválidas Scenario: Tentar acessar com senha inválida Given que o usuário está na tela de login And possui um nome de usuário válido When informar o nome de usuário válido And informar uma senha inválida And solicitar o acesso Then o sistema deve negar o acesso And exibir uma mensagem informando que as credenciais são inválidas Scenario: Tentar acessar sem informar o nome de usuário Given que o usuário está na tela de login When deixar o campo de nome de usuário vazio And informar uma senha And solicitar o acesso Then o sistema deve impedir o acesso And informar que o nome de usuário deve ser preenchido Scenario: Tentar acessar sem informar a senha Given que o usuário está na tela de login When informar um nome de usuário And deixar o campo de senha vazio And solicitar o acesso Then o sistema deve impedir o acesso And informar que a senha deve ser preenchida Scenario: Tentar acessar sem informar nome de usuário e senha Given que o usuário está na tela de login When deixar o campo de nome de usuário vazio And deixar o campo de senha vazio And solicitar o acesso Then o sistema deve impedir o acesso And informar que os campos obrigatórios devem ser preenchidos | L4: 6
A6: H1 | B6: E2 | D6: =IF(INSTRUCOES!$B$12="","",INSTRUCOES!$B$12) -> GPT-5.6 Luna (Free) | E6: =IF(INSTRUCOES!$B$13="","",INSTRUCOES!$B$13) -> Instant | F6: =IF(INSTRUCOES!$B$14="","",INSTRUCOES!$B$14) -> Não disponibilizada pela interface | G6: =IF(INSTRUCOES!$B$15="","",INSTRUCOES!$B$15) -> Não disponibilizado pela interface | H6: Você é um analista de testes de software com conhecimento em BDD e na linguagem Gherkin. A partir da história de usuário apresentada abaixo, gere cenários de teste em Gherkin que representem os comportamentos que devem ser testados no sistema. Considere as informações disponíveis na história de usuário e utilize seu conhecimento para identificar os principais cenários de teste, incluindo situações de sucesso e situações de erro ou exceção. Utilize uma estrutura válida de Gherkin, com as palavras-chave Feature, Scenario, Given, When, Then, And e But quando necessário. Não explique sua resposta. Apresente somente os cenários Gherkin. História de usuário: Como usuário do sistema, quero informar meu nome de usuário e minha senha, para acessar a área de produtos quando minhas credenciais forem válidas. | J6: Feature: Login de usuário Scenario: Acessar a área de produtos com credenciais válidas Given que o usuário está na tela de login And possui um nome de usuário válido And possui uma senha válida When informar o nome de usuário e a senha And clicar no botão de login Then o sistema deve autenticar o usuário And deve direcionar o usuário para a área de produtos Scenario: Tentar acessar a área de produtos com nome de usuário inválido Given que o usuário está na tela de login And possui uma senha válida When informar um nome de usuário inválido And informar a senha válida And clicar no botão de login Then o sistema não deve autenticar o usuário And deve informar que as credenciais são inválidas But o usuário não deve acessar a área de produtos Scenario: Tentar acessar a área de produtos com senha inválida Given que o usuário está na tela de login And possui um nome de usuário válido When informar o nome de usuário válido And informar uma senha inválida And clicar no botão de login Then o sistema não deve autenticar o usuário And deve informar que as credenciais são inválidas But o usuário não deve acessar a área de produtos Scenario: Tentar realizar login sem informar o nome de usuário Given que o usuário está na tela de login When informar uma senha válida And clicar no botão de login Then o sistema deve informar que o nome de usuário é obrigatório And não deve autenticar o usuário But o usuário não deve acessar a área de produtos Scenario: Tentar realizar login sem informar a senha Given que o usuário está na tela de login When informar um nome de usuário válido And clicar no botão de login Then o sistema deve informar que a senha é obrigatória And não deve autenticar o usuário But o usuário não deve acessar a área de produtos Scenario: Tentar realizar login sem informar nome de usuário e senha Given que o usuário está na tela de login When clicar no botão de login sem informar as credenciais Then o sistema deve informar que o nome de usuário é obrigatório And deve informar que a senha é obrigatória And não deve autenticar o usuário But o usuário não deve acessar a área de produtos | L6: 6
A8: H1 | B8: E3 | D8: =IF(INSTRUCOES!$B$12="","",INSTRUCOES!$B$12) -> GPT-5.6 Luna (Free) | E8: =IF(INSTRUCOES!$B$13="","",INSTRUCOES!$B$13) -> Instant | F8: =IF(INSTRUCOES!$B$14="","",INSTRUCOES!$B$14) -> Não disponibilizada pela interface | G8: =IF(INSTRUCOES!$B$15="","",INSTRUCOES!$B$15) -> Não disponibilizado pela interface | H8: Você é um analista de testes de software com conhecimento em BDD e na linguagem Gherkin. A partir da história de usuário apresentada abaixo, gere cenários de teste em Gherkin que representem os comportamentos que devem ser testados no sistema. Considere as informações disponíveis na história de usuário e utilize seu conhecimento para identificar os principais cenários de teste, incluindo situações de sucesso e situações de erro ou exceção. Utilize uma estrutura válida de Gherkin, com as palavras-chave Feature, Scenario, Given, When, Then, And e But quando necessário. Não explique sua resposta. Apresente somente os cenários Gherkin. História de usuário: Como usuário do sistema, quero informar meu nome de usuário e minha senha, para acessar a área de produtos quando minhas credenciais forem válidas. | J8: Feature: Login de usuário Scenario: Login com credenciais válidas Given que o usuário está na tela de login And possui um nome de usuário válido And possui uma senha válida When informar o nome de usuário e a senha And clicar no botão de login Then o sistema deve autenticar o usuário And deve permitir o acesso à área de produtos Scenario: Login com nome de usuário inválido Given que o usuário está na tela de login And possui um nome de usuário inválido And possui uma senha válida When informar o nome de usuário e a senha And clicar no botão de login Then o sistema deve impedir o acesso à área de produtos And deve exibir uma mensagem de erro Scenario: Login com senha inválida Given que o usuário está na tela de login And possui um nome de usuário válido And possui uma senha inválida When informar o nome de usuário e a senha And clicar no botão de login Then o sistema deve impedir o acesso à área de produtos And deve exibir uma mensagem de erro Scenario: Login com nome de usuário e senha inválidos Given que o usuário está na tela de login And possui um nome de usuário inválido And possui uma senha inválida When informar o nome de usuário e a senha And clicar no botão de login Then o sistema deve impedir o acesso à área de produtos And deve exibir uma mensagem de erro Scenario: Login sem informar o nome de usuário Given que o usuário está na tela de login And possui uma senha válida When não informar o nome de usuário And informar a senha And clicar no botão de login Then o sistema deve impedir o acesso à área de produtos And deve informar que o nome de usuário é obrigatório Scenario: Login sem informar a senha Given que o usuário está na tela de login And possui um nome de usuário válido When informar o nome de usuário And não informar a senha And clicar no botão de login Then o sistema deve impedir o acesso à área de produtos And deve informar que a senha é obrigatória Scenario: Login sem informar nome de usuário e senha Given que o usuário está na tela de login When não informar o nome de usuário And não informar a senha And clicar no botão de login Then o sistema deve impedir o acesso à área de produtos And deve informar que os campos são obrigatórios | L8: 7
A10: H2 | B10: E1 | D10: =IF(INSTRUCOES!$B$12="","",INSTRUCOES!$B$12) -> GPT-5.6 Luna (Free) | E10: =IF(INSTRUCOES!$B$13="","",INSTRUCOES!$B$13) -> Instant | F10: =IF(INSTRUCOES!$B$14="","",INSTRUCOES!$B$14) -> Não disponibilizada pela interface | G10: =IF(INSTRUCOES!$B$15="","",INSTRUCOES!$B$15) -> Não disponibilizado pela interface | H10: Você é um analista de testes de software com conhecimento em BDD e na linguagem Gherkin. A partir da história de usuário apresentada abaixo, gere cenários de teste em Gherkin que representem os comportamentos que devem ser testados no sistema. Considere as informações disponíveis na história de usuário e utilize seu conhecimento para identificar os principais cenários de teste, incluindo situações de sucesso e situações de erro ou exceção. Utilize uma estrutura válida de Gherkin, com as palavras-chave Feature, Scenario, Given, When, Then, And e But quando necessário. Não explique sua resposta. Apresente somente os cenários Gherkin. História de usuário: Como usuário autenticado, quero adicionar produtos ao carrinho e visualizar e gerenciar os itens selecionados, para revisar minha seleção antes de realizar o checkout. | J10: ```gherkin Feature: Gerenciamento de produtos no carrinho Scenario: Adicionar um produto ao carrinho Given que o usuário está autenticado And está na área de produtos And existe um produto disponível para compra When adicionar o produto ao carrinho Then o produto deve ser adicionado ao carrinho And o carrinho deve exibir o produto selecionado Scenario: Adicionar mais de um produto ao carrinho Given que o usuário está autenticado And está na área de produtos And existem produtos disponíveis para compra When adicionar diferentes produtos ao carrinho Then todos os produtos selecionados devem ser adicionados ao carrinho And o carrinho deve exibir todos os produtos selecionados Scenario: Visualizar os produtos adicionados ao carrinho Given que o usuário está autenticado And possui produtos adicionados ao carrinho When acessar o carrinho Then o sistema deve exibir os produtos adicionados And deve exibir as informações dos produtos selecionados Scenario: Remover um produto do carrinho Given que o usuário está autenticado And possui produtos adicionados ao carrinho When remover um produto do carrinho Then o produto deve ser removido do carrinho And o produto não deve mais ser exibido na lista de itens Scenario: Remover todos os produtos do carrinho Given que o usuário está autenticado And possui mais de um produto adicionado ao carrinho When remover todos os produtos Then o carrinho deve ficar vazio And os produtos removidos não devem ser exibidos no carrinho Scenario: Alterar a quantidade de um produto no carrinho Given que o usuário está autenticado And possui um produto adicionado ao carrinho When alterar a quantidade do produto Then o sistema deve atualizar a quantidade do produto And deve atualizar o valor correspondente no carrinho Scenario: Acessar o carrinho sem produtos adicionados Given que o usuário está autenticado And não possui produtos adicionados ao carrinho When acessar o carrinho Then o sistema deve exibir o carrinho vazio And não deve exibir produtos na lista de itens Scenario: Tentar adicionar um produto indisponível Given que o usuário está autenticado And existe um produto indisponível para compra When tentar adicionar o produto ao carrinho Then o sistema não deve adicionar o produto ao carrinho And deve informar que o produto está indisponível Scenario: Tentar acessar o carrinho sem estar autenticado Given que o usuário não está autenticado When tentar acessar o carrinho Then o sistema deve impedir o acesso ao carrinho And deve solicitar que o usuário realize a autenticação Scenario: Revisar os produtos antes do checkout Given que o usuário está autenticado And possui produtos adicionados ao carrinho When acessar o carrinho Then deve visualizar os produtos selecionados And deve poder gerenciar os itens do carrinho And deve poder revisar sua seleção antes de realizar o checkout ``` | L10: 10
A12: H2 | B12: E2 | D12: =IF(INSTRUCOES!$B$12="","",INSTRUCOES!$B$12) -> GPT-5.6 Luna (Free) | E12: =IF(INSTRUCOES!$B$13="","",INSTRUCOES!$B$13) -> Instant | F12: =IF(INSTRUCOES!$B$14="","",INSTRUCOES!$B$14) -> Não disponibilizada pela interface | G12: =IF(INSTRUCOES!$B$15="","",INSTRUCOES!$B$15) -> Não disponibilizado pela interface | H12: Você é um analista de testes de software com conhecimento em BDD e na linguagem Gherkin. A partir da história de usuário apresentada abaixo, gere cenários de teste em Gherkin que representem os comportamentos que devem ser testados no sistema. Considere as informações disponíveis na história de usuário e utilize seu conhecimento para identificar os principais cenários de teste, incluindo situações de sucesso e situações de erro ou exceção. Utilize uma estrutura válida de Gherkin, com as palavras-chave Feature, Scenario, Given, When, Then, And e But quando necessário. Não explique sua resposta. Apresente somente os cenários Gherkin. História de usuário: Como usuário autenticado, quero adicionar produtos ao carrinho e visualizar e gerenciar os itens selecionados, para revisar minha seleção antes de realizar o checkout. | J12: Feature: Gerenciamento de produtos no carrinho Scenario: Adicionar um produto ao carrinho Given que o usuário está autenticado And que existe um produto disponível para compra When o usuário adiciona o produto ao carrinho Then o produto deve ser adicionado ao carrinho And o carrinho deve exibir o produto selecionado Scenario: Adicionar mais de um produto ao carrinho Given que o usuário está autenticado And que existem produtos disponíveis para compra When o usuário adiciona diferentes produtos ao carrinho Then todos os produtos selecionados devem ser adicionados ao carrinho And o carrinho deve exibir todos os produtos selecionados Scenario: Visualizar os itens adicionados ao carrinho Given que o usuário está autenticado And que existem produtos adicionados ao carrinho When o usuário acessa o carrinho Then os produtos adicionados devem ser exibidos And as informações dos produtos devem estar disponíveis para revisão Scenario: Alterar a quantidade de um produto no carrinho Given que o usuário está autenticado And que existe um produto no carrinho When o usuário altera a quantidade do produto Then a quantidade do produto deve ser atualizada And o valor correspondente deve ser atualizado Scenario: Remover um produto do carrinho Given que o usuário está autenticado And que existe um produto no carrinho When o usuário remove o produto do carrinho Then o produto não deve mais ser exibido no carrinho Scenario: Remover todos os produtos do carrinho Given que o usuário está autenticado And que existem produtos no carrinho When o usuário remove todos os produtos Then o carrinho deve ficar vazio Scenario: Acessar o carrinho sem produtos adicionados Given que o usuário está autenticado And que o carrinho está vazio When o usuário acessa o carrinho Then o sistema deve informar que não existem produtos no carrinho Scenario: Tentar adicionar um produto indisponível Given que o usuário está autenticado And que o produto não está disponível para compra When o usuário tenta adicionar o produto ao carrinho Then o produto não deve ser adicionado ao carrinho And o sistema deve informar que o produto não está disponível Scenario: Tentar acessar o carrinho sem estar autenticado Given que o usuário não está autenticado When o usuário tenta acessar o carrinho Then o sistema deve solicitar que o usuário realize a autenticação Scenario: Manter os produtos adicionados ao navegar pelo sistema Given que o usuário está autenticado And que existem produtos adicionados ao carrinho When o usuário navega para outra página do sistema Then os produtos devem permanecer no carrinho And a seleção do usuário deve ser mantida | L12: 10
A14: H2 | B14: E3 | D14: =IF(INSTRUCOES!$B$12="","",INSTRUCOES!$B$12) -> GPT-5.6 Luna (Free) | E14: =IF(INSTRUCOES!$B$13="","",INSTRUCOES!$B$13) -> Instant | F14: =IF(INSTRUCOES!$B$14="","",INSTRUCOES!$B$14) -> Não disponibilizada pela interface | G14: =IF(INSTRUCOES!$B$15="","",INSTRUCOES!$B$15) -> Não disponibilizado pela interface | H14: Você é um analista de testes de software com conhecimento em BDD e na linguagem Gherkin. A partir da história de usuário apresentada abaixo, gere cenários de teste em Gherkin que representem os comportamentos que devem ser testados no sistema. Considere as informações disponíveis na história de usuário e utilize seu conhecimento para identificar os principais cenários de teste, incluindo situações de sucesso e situações de erro ou exceção. Utilize uma estrutura válida de Gherkin, com as palavras-chave Feature, Scenario, Given, When, Then, And e But quando necessário. Não explique sua resposta. Apresente somente os cenários Gherkin. História de usuário: Como usuário autenticado, quero adicionar produtos ao carrinho e visualizar e gerenciar os itens selecionados, para revisar minha seleção antes de realizar o checkout. | J14: Feature: Adicionar e gerenciar produtos no carrinho Scenario: Adicionar um produto ao carrinho Given que o usuário está autenticado And que existe um produto disponível When o usuário adiciona o produto ao carrinho Then o produto deve ser adicionado ao carrinho And o produto deve ser exibido na lista de itens Scenario: Adicionar múltiplos produtos ao carrinho Given que o usuário está autenticado And que existem produtos disponíveis When o usuário adiciona diferentes produtos ao carrinho Then todos os produtos selecionados devem ser adicionados ao carrinho And todos os produtos devem ser exibidos na lista de itens Scenario: Visualizar os produtos do carrinho Given que o usuário está autenticado And que existem produtos adicionados ao carrinho When o usuário acessa o carrinho Then os produtos adicionados devem ser exibidos And suas informações devem estar disponíveis para revisão Scenario: Alterar a quantidade de um produto Given que o usuário está autenticado And que existe um produto no carrinho When o usuário altera a quantidade do produto Then a quantidade do produto deve ser atualizada And o valor total do produto deve ser atualizado Scenario: Remover um produto do carrinho Given que o usuário está autenticado And que existe um produto no carrinho When o usuário remove o produto Then o produto não deve mais ser exibido no carrinho And o valor total do carrinho deve ser atualizado Scenario: Visualizar o carrinho vazio Given que o usuário está autenticado And que não existem produtos no carrinho When o usuário acessa o carrinho Then o sistema deve informar que o carrinho está vazio Scenario: Tentar adicionar um produto indisponível Given que o usuário está autenticado And que o produto não está disponível para compra When o usuário tenta adicionar o produto ao carrinho Then o produto não deve ser adicionado ao carrinho And o sistema deve informar que o produto não está disponível Scenario: Acessar o carrinho sem autenticação Given que o usuário não está autenticado When o usuário tenta acessar o carrinho Then o sistema deve solicitar a autenticação do usuário And o carrinho não deve ser exibido Scenario: Manter os produtos do carrinho durante a navegação Given que o usuário está autenticado And que existem produtos adicionados ao carrinho When o usuário navega para outra página And retorna ao carrinho Then os produtos adicionados anteriormente devem continuar no carrinho | L14: 9
A16: H3 | B16: E1 | D16: =IF(INSTRUCOES!$B$12="","",INSTRUCOES!$B$12) -> GPT-5.6 Luna (Free) | E16: =IF(INSTRUCOES!$B$13="","",INSTRUCOES!$B$13) -> Instant | F16: =IF(INSTRUCOES!$B$14="","",INSTRUCOES!$B$14) -> Não disponibilizada pela interface | G16: =IF(INSTRUCOES!$B$15="","",INSTRUCOES!$B$15) -> Não disponibilizado pela interface | H16: Você é um analista de testes de software com conhecimento em BDD e na linguagem Gherkin. A partir da história de usuário apresentada abaixo, gere cenários de teste em Gherkin que representem os comportamentos que devem ser testados no sistema. Considere as informações disponíveis na história de usuário e utilize seu conhecimento para identificar os principais cenários de teste, incluindo situações de sucesso e situações de erro ou exceção. Utilize uma estrutura válida de Gherkin, com as palavras-chave Feature, Scenario, Given, When, Then, And e But quando necessário. Não explique sua resposta. Apresente somente os cenários Gherkin. História de usuário: Como usuário autenticado, quero informar meus dados e finalizar a compra, para concluir o processo de aquisição dos produtos selecionados. | J16: Feature: Finalização da compra Scenario: Finalizar compra com dados válidos Given que o usuário está autenticado And que existem produtos no carrinho And que os dados de entrega estão preenchidos corretamente And que os dados de pagamento estão válidos When o usuário finaliza a compra Then o pedido deve ser criado com sucesso And o sistema deve exibir a confirmação da compra Scenario: Finalizar compra com dados de entrega obrigatórios preenchidos Given que o usuário está autenticado And que existem produtos no carrinho When o usuário informa todos os dados de entrega obrigatórios And prossegue para a finalização da compra Then os dados informados devem ser aceitos pelo sistema Scenario: Tentar finalizar compra com dados obrigatórios ausentes Given que o usuário está autenticado And que existem produtos no carrinho And que um ou mais dados obrigatórios não foram preenchidos When o usuário tenta finalizar a compra Then a compra não deve ser finalizada And o sistema deve informar os campos que precisam ser preenchidos Scenario: Finalizar compra com dados de pagamento inválidos Given que o usuário está autenticado And que existem produtos no carrinho And que os dados de pagamento são inválidos When o usuário tenta finalizar a compra Then a compra não deve ser finalizada And o sistema deve informar que os dados de pagamento são inválidos Scenario: Finalizar compra com carrinho vazio Given que o usuário está autenticado And que o carrinho está vazio When o usuário tenta finalizar a compra Then a compra não deve ser finalizada And o sistema deve informar que não existem produtos no carrinho Scenario: Cancelar a finalização da compra Given que o usuário está autenticado And que existem produtos no carrinho And que os dados da compra foram preenchidos When o usuário cancela a finalização da compra Then o pedido não deve ser criado And os produtos devem permanecer no carrinho Scenario: Tentar finalizar compra sem estar autenticado Given que o usuário não está autenticado And que existem produtos no carrinho When o usuário tenta finalizar a compra Then o sistema deve solicitar a autenticação And a compra não deve ser finalizada Scenario: Compra finalizada com sucesso Given que o usuário está autenticado And que existem produtos no carrinho And que todos os dados necessários foram informados corretamente When o usuário confirma a compra Then o pedido deve ser registrado And o sistema deve apresentar o número do pedido And o sistema deve informar que a compra foi concluída | L16: 8
A18: H3 | B18: E2 | D18: =IF(INSTRUCOES!$B$12="","",INSTRUCOES!$B$12) -> GPT-5.6 Luna (Free) | E18: =IF(INSTRUCOES!$B$13="","",INSTRUCOES!$B$13) -> Instant | F18: =IF(INSTRUCOES!$B$14="","",INSTRUCOES!$B$14) -> Não disponibilizada pela interface | G18: =IF(INSTRUCOES!$B$15="","",INSTRUCOES!$B$15) -> Não disponibilizado pela interface | H18: Você é um analista de testes de software com conhecimento em BDD e na linguagem Gherkin. A partir da história de usuário apresentada abaixo, gere cenários de teste em Gherkin que representem os comportamentos que devem ser testados no sistema. Considere as informações disponíveis na história de usuário e utilize seu conhecimento para identificar os principais cenários de teste, incluindo situações de sucesso e situações de erro ou exceção. Utilize uma estrutura válida de Gherkin, com as palavras-chave Feature, Scenario, Given, When, Then, And e But quando necessário. Não explique sua resposta. Apresente somente os cenários Gherkin. História de usuário: Como usuário autenticado, quero informar meus dados e finalizar a compra, para concluir o processo de aquisição dos produtos selecionados. | J18: Feature: Finalização da compra Scenario: Finalizar compra com dados válidos Given que o usuário está autenticado And que existem produtos no carrinho And que os dados necessários para a compra estão preenchidos corretamente When o usuário confirma a compra Then o pedido deve ser criado com sucesso And o sistema deve exibir a confirmação da compra Scenario: Finalizar compra sem informar um dado obrigatório Given que o usuário está autenticado And que existem produtos no carrinho And que um dado obrigatório não foi informado When o usuário tenta finalizar a compra Then a compra não deve ser finalizada And o sistema deve informar o dado que precisa ser preenchido Scenario: Informar dados de entrega inválidos Given que o usuário está autenticado And que existem produtos no carrinho When o usuário informa dados de entrega inválidos And tenta finalizar a compra Then a compra não deve ser finalizada And o sistema deve informar que os dados de entrega são inválidos Scenario: Informar dados de pagamento inválidos Given que o usuário está autenticado And que existem produtos no carrinho And que os dados de pagamento são inválidos When o usuário tenta finalizar a compra Then a compra não deve ser finalizada And o sistema deve informar que os dados de pagamento são inválidos Scenario: Finalizar compra com carrinho vazio Given que o usuário está autenticado And que o carrinho está vazio When o usuário tenta finalizar a compra Then a compra não deve ser finalizada And o sistema deve informar que não existem produtos selecionados Scenario: Finalizar compra sem estar autenticado Given que o usuário não está autenticado And que existem produtos no carrinho When o usuário tenta finalizar a compra Then o sistema deve solicitar a autenticação And a compra não deve ser finalizada Scenario: Cancelar a finalização da compra Given que o usuário está autenticado And que existem produtos no carrinho And que os dados da compra foram preenchidos When o usuário cancela a finalização da compra Then o pedido não deve ser criado And os produtos devem permanecer no carrinho Scenario: Exibir confirmação após finalizar a compra Given que o usuário está autenticado And que existem produtos no carrinho And que todos os dados necessários foram preenchidos corretamente When o usuário finaliza a compra Then o sistema deve exibir uma mensagem de confirmação And o sistema deve apresentar as informações do pedido | L18: 8
A20: H3 | B20: E3 | D20: =IF(INSTRUCOES!$B$12="","",INSTRUCOES!$B$12) -> GPT-5.6 Luna (Free) | E20: =IF(INSTRUCOES!$B$13="","",INSTRUCOES!$B$13) -> Instant | F20: =IF(INSTRUCOES!$B$14="","",INSTRUCOES!$B$14) -> Não disponibilizada pela interface | G20: =IF(INSTRUCOES!$B$15="","",INSTRUCOES!$B$15) -> Não disponibilizado pela interface | H20: Você é um analista de testes de software com conhecimento em BDD e na linguagem Gherkin. A partir da história de usuário apresentada abaixo, gere cenários de teste em Gherkin que representem os comportamentos que devem ser testados no sistema. Considere as informações disponíveis na história de usuário e utilize seu conhecimento para identificar os principais cenários de teste, incluindo situações de sucesso e situações de erro ou exceção. Utilize uma estrutura válida de Gherkin, com as palavras-chave Feature, Scenario, Given, When, Then, And e But quando necessário. Não explique sua resposta. Apresente somente os cenários Gherkin. História de usuário: Como usuário autenticado, quero informar meus dados e finalizar a compra, para concluir o processo de aquisição dos produtos selecionados. | J20: Feature: Finalização da compra Scenario: Finalizar compra com dados válidos Given que o usuário está autenticado And que existem produtos selecionados no carrinho And que os dados necessários para a compra estão preenchidos corretamente When o usuário confirma a compra Then o pedido deve ser finalizado com sucesso And o sistema deve exibir a confirmação da compra Scenario: Finalizar compra sem informar dados obrigatórios Given que o usuário está autenticado And que existem produtos selecionados no carrinho When o usuário tenta finalizar a compra sem preencher um ou mais dados obrigatórios Then a compra não deve ser finalizada And o sistema deve informar quais dados precisam ser preenchidos Scenario: Informar dados de entrega inválidos Given que o usuário está autenticado And que existem produtos selecionados no carrinho When o usuário informa dados de entrega inválidos And tenta finalizar a compra Then a compra não deve ser finalizada And o sistema deve informar que os dados de entrega são inválidos Scenario: Informar dados de pagamento inválidos Given que o usuário está autenticado And que existem produtos selecionados no carrinho When o usuário informa dados de pagamento inválidos And tenta finalizar a compra Then a compra não deve ser finalizada And o sistema deve informar que os dados de pagamento são inválidos Scenario: Finalizar compra com carrinho vazio Given que o usuário está autenticado And que o carrinho não possui produtos When o usuário tenta finalizar a compra Then a compra não deve ser finalizada And o sistema deve informar que o carrinho está vazio Scenario: Tentar finalizar compra sem estar autenticado Given que o usuário não está autenticado And que existem produtos selecionados no carrinho When o usuário tenta finalizar a compra Then o sistema deve solicitar a autenticação And a compra não deve ser finalizada Scenario: Cancelar a finalização da compra Given que o usuário está autenticado And que existem produtos selecionados no carrinho And que os dados necessários foram preenchidos corretamente When o usuário cancela a finalização da compra Then o pedido não deve ser criado And os produtos devem permanecer no carrinho Scenario: Exibir os dados do pedido após a finalização Given que o usuário está autenticado And que existem produtos selecionados no carrinho And que todos os dados necessários foram preenchidos corretamente When o usuário finaliza a compra Then o sistema deve exibir uma mensagem de confirmação And o sistema deve apresentar os dados do pedido | L20: 8

Sheet C1
A1: C1 — abordagem com entrada estruturada
A2: História de usuário, critérios de aceitação e regras de negócio estruturadas, com prompt parametrizado e verificação estrutural.
A3: História ID | B3: Execução ID | C3: Data | D3: Modelo | E3: Plano | F3: Prompt utilizado | G3: Entrada fornecida | H3: Saída bruta da IA | I3: Critérios de aceitação utilizados (IDs) | J3: Regras de negócio utilizadas (IDs) | K3: Versão do prompt parametrizado | L3: Arquivo da saída bruta (caminho ou link) | M3: Quantidade de cenários gerados | N3: Observações
A4: H1 | B4: E1 | C4: 46299 | D4: =IF(INSTRUCOES!$B$12="","",INSTRUCOES!$B$12) -> GPT-5.6 Luna (Free) | E4: Free | F4: Prompt C1 — versão 1.0 | G4: História H01 + CA01–CA07 + RN02–RN07 | H4: 6 cenários Gherkin / referência ao arquivo salvo | I4: CA01–CA07 | J4: RN02–RN07 | K4: C1-v1.0 | L4: https://docs.google.com/document/d/1hycAhxcLjVdIZX4-2e860M2vrz7OH5cQjoRqGlqhqzk/edit?tab=t.0 | M4: 6 | N4: Saída bruta registrada sem alterações ou correções.
A5: H1 | B5: E2 | C5: 46299 | D5: =IF(INSTRUCOES!$B$12="","",INSTRUCOES!$B$12) -> GPT-5.6 Luna (Free) | E5: Free | F5: Prompt C1 — versão 1.0 | G5: História H01 + CA01–CA07 + RN02–RN07 | H5: 6 cenários Gherkin | I5: CA01–CA07 | J5: RN02–RN07 | K5: C1-v1.0 | L5: https://docs.google.com/document/d/1hycAhxcLjVdIZX4-2e860M2vrz7OH5cQjoRqGlqhqzk/edit?tab=t.0 | M5: 6 | N5: Saída bruta registrada sem alterações ou correções.
A6: H1 | B6: E3 | C6: 46299 | D6: =IF(INSTRUCOES!$B$12="","",INSTRUCOES!$B$12) -> GPT-5.6 Luna (Free) | E6: Free | F6: Prompt C1 — versão 1.0 | G6: História H01 + CA01–CA07 + RN02–RN07 | H6: 6 cenários Gherkin | I6: CA01–CA07 | J6: RN02–RN07 | K6: C1-v1.0 | L6: https://docs.google.com/document/d/1hycAhxcLjVdIZX4-2e860M2vrz7OH5cQjoRqGlqhqzk/edit?tab=t.0 | M6: 6 | N6: Saída bruta registrada sem alterações ou correções.
A8: H2 | B8: E1 | C8: 46299 | D8: =IF(INSTRUCOES!$B$12="","",INSTRUCOES!$B$12) -> GPT-5.6 Luna (Free) | E8: Free | F8: Prompt C1 — versão 1.0 | G8: História H02 + CA08–CA14 + RN08–RN14 | H8: 7 cenários Gherkin | I8: CA08–CA14 | J8: RN08–RN14 | K8: C1-v1.0 | L8: https://docs.google.com/document/d/1hycAhxcLjVdIZX4-2e860M2vrz7OH5cQjoRqGlqhqzk/edit?tab=t.0 | M8: 7 | N8: Saída bruta registrada sem alterações ou correções.
A9: H2 | B9: E2 | C9: 46299 | D9: =IF(INSTRUCOES!$B$12="","",INSTRUCOES!$B$12) -> GPT-5.6 Luna (Free) | E9: Free | F9: Prompt C1 — versão 1.0 | G9: História H02 + CA08–CA14 + RN08–RN14 | H9: 7 cenários Gherkin | I9: CA08–CA14 | J9: RN08–RN14 | K9: C1-v1.0 | L9: https://docs.google.com/document/d/1hycAhxcLjVdIZX4-2e860M2vrz7OH5cQjoRqGlqhqzk/edit?tab=t.0 | M9: 7 | N9: Saída bruta registrada sem alterações ou correções.
A10: H2 | B10: E3 | C10: 46299 | D10: =IF(INSTRUCOES!$B$12="","",INSTRUCOES!$B$12) -> GPT-5.6 Luna (Free) | E10: Free | F10: Prompt C1 — versão 1.0 | G10: História H02 + CA08–CA14 + RN08–RN14 | H10: 7 cenários Gherkin | I10: CA08–CA14 | J10: RN08–RN14 | K10: C1-v1.0 | L10: https://docs.google.com/document/d/1hycAhxcLjVdIZX4-2e860M2vrz7OH5cQjoRqGlqhqzk/edit?tab=t.0 | M10: 7 | N10: Saída bruta registrada sem alterações ou correções.
A12: H3 | B12: E1 | C12: 46299 | D12: =IF(INSTRUCOES!$B$12="","",INSTRUCOES!$B$12) -> GPT-5.6 Luna (Free) | E12: Free | F12: Prompt C1 — versão 1.0 | G12: História H03 + CA15–CA24 + RN15–RN24 | H12: 10 cenários Gherkin | I12: CA15–CA24 | J12: RN15–RN24 | K12: C1-v1.0 | L12: https://docs.google.com/document/d/1hycAhxcLjVdIZX4-2e860M2vrz7OH5cQjoRqGlqhqzk/edit?tab=t.0 | M12: 10 | N12: Saída bruta registrada sem alterações ou correções.
A13: H3 | B13: E2 | C13: 46299 | D13: =IF(INSTRUCOES!$B$12="","",INSTRUCOES!$B$12) -> GPT-5.6 Luna (Free) | E13: Free | F13: Prompt C1 — versão 1.0 | G13: História H03 + CA15–CA24 + RN15–RN24 | H13: 10 cenários Gherkin | I13: CA15–CA24 | J13: RN15–RN24 | K13: C1-v1.0 | L13: https://docs.google.com/document/d/1hycAhxcLjVdIZX4-2e860M2vrz7OH5cQjoRqGlqhqzk/edit?tab=t.0 | M13: 10 | N13: Saída bruta registrada sem alterações ou correções.
A14: H3 | B14: E3 | C14: 46299 | D14: =IF(INSTRUCOES!$B$12="","",INSTRUCOES!$B$12) -> GPT-5.6 Luna (Free) | E14: Free | F14: Prompt C1 — versão 1.0 | G14: História H03 + CA15–CA24 + RN15–RN24 | H14: 10 cenários Gherkin | I14: CA15–CA24 | J14: RN15–RN24 | K14: C1-v1.0 | L14: https://docs.google.com/document/d/1hycAhxcLjVdIZX4-2e860M2vrz7OH5cQjoRqGlqhqzk/edit?tab=t.0 | M14: 10 | N14: Saída bruta registrada sem alterações ou correções.

Sheet C2
A1: C2 — processo estruturado completo
A2: Entradas de C1 acrescidas de tabela de decisão e contexto do sistema, com validação humana e refinamento. Uma linha por iteração: a iteração 1 registra a geração inicial; as seguintes registram os refinamentos.
A3: História ID | B3: Execução ID | C3: Data | D3: Modelo | E3: Plano | F3: Prompt utilizado | G3: Entrada fornecida | H3: Saída bruta da IA | I3: Critérios de aceitação utilizados (IDs) | J3: Regras de negócio utilizadas (IDs) | K3: Tabela de decisão utilizada (IDs) | L3: Contexto do sistema fornecido | M3: Versão do prompt parametrizado | N3: Arquivo da saída bruta (caminho ou link) | O3: Quantidade de cenários gerados | P3: Observações
A4: H1 | B4: E1 | C4: 46299 | D4: =IF(INSTRUCOES!$B$12="","",INSTRUCOES!$B$12) -> GPT-5.6 Luna (Free) | E4: Free | F4: Prompt C2 — versão 1.0 | G4: História H01 + CA01–CA07 + RN02–RN07 + tabela de decisão H01 + contexto do sistema | H4: 6 cenários Gherkin + seção de lacunas e premissas | I4: CA01–CA07 | J4: RN02–RN07 | K4: H01 — Tabela de decisão de autenticação | L4: O sistema é uma aplicação web de comércio eletrônico. A funcionalidade analisada corresponde à autenticação de usuários. O usuário acessa a tela de login e informa nome de usuário e senha. Quando as credenciais são válidas, o sistema permite o acesso à área de produtos. Quando as credenciais são inválidas ou estão incompletas, o acesso não deve ser permitido e o sistema deve apresentar a mensagem ou comportamento de erro correspondente. Usuários bloqueados também não devem obter acesso ao sistema. | M4: C2-v1.0 | N4: https://docs.google.com/document/d/1hycAhxcLjVdIZX4-2e860M2vrz7OH5cQjoRqGlqhqzk/edit?tab=t.0 | O4: 6 | P4: Saída bruta registrada sem alterações ou correções.
A5: H1 | B5: E2 | C5: 46299 | D5: =IF(INSTRUCOES!$B$12="","",INSTRUCOES!$B$12) -> GPT-5.6 Luna (Free) | E5: Free | F5: Prompt C2 — versão 1.0 | G5: História H01 + CA01–CA07 + RN02–RN07 + tabela de decisão H01 + contexto do sistema H01 | H5: 6 cenários Gherkin | I5: CA01–CA07 | J5: RN02–RN07 | K5: H01 — Tabela de decisão de autenticação | L5: H01 — Contexto do sistema de autenticação | M5: C2-v1.0 | N5: https://docs.google.com/document/d/1hycAhxcLjVdIZX4-2e860M2vrz7OH5cQjoRqGlqhqzk/edit?tab=t.0 | O5: 6 | P5: Saída bruta registrada sem alterações ou correções.
A6: H1 | B6: E3 | C6: 46299 | D6: =IF(INSTRUCOES!$B$12="","",INSTRUCOES!$B$12) -> GPT-5.6 Luna (Free) | E6: Free | F6: Prompt C2 — versão 1.0 | G6: História H01 + CA01–CA07 + RN02–RN07 + tabela de decisão H01 + contexto do sistema H01 | H6: 6 cenários Gherkin | I6: CA01–CA07 | J6: RN02–RN07 | K6: H01 — Tabela de decisão de autenticação | L6: H01 — Contexto do sistema de autenticação | M6: C2-v1.0 | N6: https://docs.google.com/document/d/1hycAhxcLjVdIZX4-2e860M2vrz7OH5cQjoRqGlqhqzk/edit?tab=t.0 | O6: 6 | P6: Saída bruta registrada sem alterações ou correções.
A8: H2 | B8: E1 | C8: 46299 | D8: =IF(INSTRUCOES!$B$12="","",INSTRUCOES!$B$12) -> GPT-5.6 Luna (Free) | E8: Free | F8: Prompt C2 — versão 1.0 | G8: História H02 + CA08–CA14 + RN08–RN14 + tabela de decisão H02 + contexto do sistema H02 | H8: 7 cenários Gherkin | I8: CA08–CA14 | J8: RN08–RN14 | K8: TD08–TD13 | L8: H02 — Contexto do sistema de gerenciamento do carrinho | M8: C2-v1.0 | N8: https://docs.google.com/document/d/1hycAhxcLjVdIZX4-2e860M2vrz7OH5cQjoRqGlqhqzk/edit?tab=t.0 | O8: 7 | P8: Saída bruta registrada sem alterações ou correções.
